<?xml version="1.0"?>

<robot name="inmoov" xmlns:xacro="http://ros.org/wiki/xacro">

<xacro:include filename="$(find inmoov_description)/urdf/materials.urdf.xacro" />

<xacro:property name="pi" value="3.1415926" />
  
<xacro:property name="waist_rotate_min" value="${-70.0/180*pi}" />
<xacro:property name="waist_rotate_max" value="${70.0/180*pi}" />
<xacro:property name="waist_lean_min" value="${-30.0/180*pi}" />
<xacro:property name="waist_lean_max" value="${30.0/180*pi}" />
<xacro:property name="waist_front_min" value="${-20.0/180*pi}" />
<xacro:property name="waist_front_max" value="${-20.0/180*pi}" />


<xacro:macro name="torso" params="side covers">

  <link name="mid_stomach">
    <visual>
      <geometry>
        <mesh filename="package://inmoov_description/meshes/mid_stomach.stl" scale="0.001 0.001 0.001"/>
      </geometry>
      <origin rpy="0 0 0" xyz="0 0 1.152"/>
      <xacro:frame_color/>
    </visual>
  </link>

  <link name="disk">
    <visual>
      <geometry>
        <mesh filename="package://inmoov_description/meshes/disk.stl" scale="0.001 0.001 0.001"/>
      </geometry>
      <origin rpy="0 0 0" xyz="0 0.046 0"/>
      <xacro:cover_color/>
    </visual>
  </link>

  <link name="top_stomach">
    <visual>
      <geometry>
        <mesh filename="package://inmoov_description/meshes/top_stomach.stl" scale="0.001 0.001 0.001"/>
      </geometry>
      <origin rpy="0 0 0" xyz="0 0 0"/>
      <xacro:frame_color/>
    </visual>
  </link>

  <link name="torso">
    <visual>
      <geometry>
        <mesh filename="package://inmoov_description/meshes/torso.stl" scale="0.001 0.001 0.001"/>
      </geometry>
      <origin rpy="0 0 0" xyz="0 0 0"/>
      <xacro:frame_color/>
    </visual>
  </link>

  <link name="kinect">
    <visual>
      <geometry>
        <mesh filename="package://inmoov_description/meshes/kinectone.stl" scale="0.001 0.001 0.001"/>
      </geometry>
      <origin rpy="0 0 0" xyz="0 0 0"/>
      <xacro:kinect_color/>
    </visual>
  </link>

  <link name="chestplate">
    <visual>
      <geometry>
        <mesh filename="package://inmoov_description/meshes/chest.stl" scale="0.001 0.001 0.001"/>
      </geometry>
      <origin rpy="0 0 0" xyz="0 0 0"/>
      <xacro:cover_color/>
    </visual>
  </link>


  <joint name="waist_rotate" type="revolute">
   <axis xyz="0 0 1"/>
<limit effort="1000.0" lower="${waist_rotate_min}" upper="${waist_rotate_max}" velocity="0.5"/>
      <origin rpy="0 0 0" xyz="0 0 1.152"/>
    <parent link="mid_stomach"/>
    <child link="top_stomach"/>
  </joint>

  <joint name="disk" type="fixed">

      <origin rpy="0 0 0" xyz="0 0 0.09"/>
    <parent link="top_stomach"/>
    <child link="disk"/>
  </joint>

  <joint name="waist_lean" type="revolute">
   <axis xyz="0 1 0"/>
<limit effort="1000.0" lower="${waist_lean_min}" upper="${waist_lean_max}" velocity="0.5"/>
<origin rpy="0 0 0" xyz="0 0 0.11"/>
    <parent link="top_stomach"/>
    <child link="torso"/>
  </joint>

<!--
  <joint name="waist_front" type="fixed">
   <axis xyz="1 0 0"/>
<limit effort="1000.0" lower="${waist_lean_min}" upper="${waist_lean_max}" velocity="0.5"/> 
<origin rpy="0 0 0" xyz="0 0 0.11"/>
    <parent link="top_stomach"/>
    <child link="torso"/>
  </joint>
-->
  <link name="kinect_frame"/>
  <joint name="kinect_frame_joint" type="fixed">
     <origin xyz="0.095 0.0 0.0" rpy="${-pi/2} 0 ${pi} " />
     <parent link="kinect" />
     <child link="kinect_frame" />
  </joint>




  <joint name="chestplate" type="fixed">
<origin rpy="0 0 0" xyz="0 0.039 0.025"/>
    <parent link="torso"/>
    <child link="chestplate"/>
  </joint>

  <joint name="kinect" type="fixed">
<origin rpy="0 0 0" xyz="0 0 0.066"/>
    <parent link="torso"/>
    <child link="kinect"/>
  </joint>

</xacro:macro>

</robot>
